Workbook

Sheet Introducir datos
B1: coxalL | C1: coxalA | D1: esternon | E1: femur | F1: tibiotarso | G1: tarsometatarso | H1: Craneo a | I1: Craneo l | J1: humero | K1: cubito | L1: radio
A2: Introducir datos | M2: Escribir solo en lo verde | P2: =SUM(B2:L2) -> 0
E3: Importante | G3: Importante | K3: Importante
A4: Posibles especies
A5: =IF(P2=0,"",IFERROR(IF(Formulas!P10=0,,"Abejero: "&(TEXT(Formulas!P10,"0,0%"))&" ")&IF(Formulas!P18=0,,"Alcotán: "&(TEXT(Formulas!P18,"0,0%"))&" ")&IF(Formulas!P26=0,,"Alimoche: "&(TEXT(Formulas!P26,"0,0%"))&" ")&IF(Formulas!P34=0,,"Azor: "&(TEXT(Formulas!P34,"0,0%"))&" ")&IF(Formulas!P42=0,,"Buitre leonado: "&(TEXT(Formulas!P42,"0,0%"))&" ")&IF(Formulas!P50=0,,"Búho real: "&(TEXT(Formulas!P50,"0,0%"))&" ")&IF(Formulas!P58=0,,"Buitre negro: "&(TEXT(Formulas!P58,"0,0%"))&" ")&IF(Formulas!P66=0,,"Calzada: "&(TEXT(Formulas!P66,"0,0%"))&" ")&IF(Formulas!P74=0,,"C.Primilla: "&(TEXT(Formulas!P74,"0,0%"))&" ")&IF(Formulas!P82=0,,"C.Vulgar: "&(TEXT(Formulas!P82,"0,0%"))&" ")&IF(Formulas!P90=0,,"Circus Aeruginosus: "&(TEXT(Formulas!P90,"0,0%"))&" ")&IF(Formulas!P98=0,,"Circus Cyaneus: "&(TEXT(Formulas!P98,"0,0%"))&" ")&IF(Formulas!P106=0,,"Circus Pygargus: "&(TEXT(Formulas!P106,"0,0%"))&" ")&IF(Formulas!P114=0,,"Culebrera: "&(TEXT(Formulas!P114,"0,0%"))&" ")&IF(Formulas!P122=0,,"Elanus caerulus: "&(TEXT(Formulas!P122,"0,0%"))&" ")&IF(Formulas!P130=0,,"Falco columbaris: "&(TEXT(Formulas!P130,"0,0%"))&" ")&IF(Formulas!P138=0,,"Falco peregrinus: "&(TEXT(Formulas!P138,"0,0%"))&" ")&IF(Formulas!P146=0,,"Gavilán: "&(TEXT(Formulas!P146,"0,0%"))&" ")&IF(Formulas!P154=0,,"Imperial: "&(TEXT(Formulas!P154,"0,0%"))&" ")&IF(Formulas!P162=0,,"Milano negro: "&(TEXT(Formulas!P162,"0,0%"))&" ")&IF(Formulas!P170=0,,"Milano real: "&(TEXT(Formulas!P170,"0,0%"))&" ")&IF(Formulas!P178=0,,"Perdicera: "&(TEXT(Formulas!P178,"0,0%"))&" ")&IF(Formulas!P186=0,,"Pescadora: "&(TEXT(Formulas!P186,"0,0%"))&" ")&IF(Formulas!P194=0,,"Qebrantahuesos: "&(TEXT(Formulas!P194,"0,0%"))&" ")&IF(Formulas!P202=0,,"Ratonero: "&(TEXT(Formulas!P202,"0,0%"))&" ")&IF(Formulas!P210=0,,"Real: "&(TEXT(Formulas!P210,"0,0%"))&" "),"Las medidas no son compatibles con ninguna especie"))
N8: Abejero
N9: Alcotán
N10: Alimoche
N11: Azor
N12: B.Leonado
N13: Buho real
N14: Buitre negro
N15: Calzada
N16: C. Primilla
N17: C. Vulgar
N18: Circus Aeroginosus
N19: Circus cyaneus
... N33: Real

Sheet Formulas
B1: coxalL | C1: coxalA | D1: esternon | E1: femur | F1: tibiotarso | G1: tarsometatarso | H1: Craneo a | I1: Craneo l | J1: humero | K1: cubito | L1: radio
A2: Introducir datos | B2: ='Introducir datos'!B2 | C2: ='Introducir datos'!C2 | D2: ='Introducir datos'!D2 | E2: ='Introducir datos'!E2 | F2: ='Introducir datos'!F2 | G2: ='Introducir datos'!G2 | H2: ='Introducir datos'!H2 | I2: ='Introducir datos'!I2 | ... L2: ='Introducir datos'!L2
B4: coxalL | C4: coxalA | D4: esternon | E4: femur | F4: tibiotarso | G4: tarsometatarso | H4: Craneo a | I4: Craneo l | J4: humero | K4: cubito | L4: radio
A5: Abejero
A6: Media | B6: =AVERAGE('Base de datos'!C2:C28) -> 57.07037 | C6: =AVERAGE('Base de datos'!D2:D28) -> 32.966667 | D6: =AVERAGE('Base de datos'!E2:E28) -> 63.612755 | E6: =AVERAGE('Base de datos'!F2:F28) -> 56.481481 | F6: =AVERAGE('Base de datos'!G2:G28) -> 86.983335 | G6: =AVERAGE('Base de datos'!H2:H28) -> 52.514971 | H6: =AVERAGE('Base de datos'!I2:I28) -> 38.481574 | I6: =AVERAGE('Base de datos'!J2:J28) -> 74.209985 | ... L6: =AVERAGE('Base de datos'!M2:M28) -> 111.81431
A7: Desv Típica | B7: =STDEV('Base de datos'!C2:C28) -> 2.8225486 | C7: =STDEV('Base de datos'!D2:D28) -> 2.1654632 | D7: =STDEV('Base de datos'!E2:E28) -> 3.1492154 | E7: =STDEV('Base de datos'!F2:F28) -> 2.3475088 | F7: =STDEV('Base de datos'!G2:G28) -> 3.2619195 | G7: =STDEV('Base de datos'!H2:H28) -> 2.2901204 | H7: =STDEV('Base de datos'!I2:I28) -> 1.3721855 | I7: =STDEV('Base de datos'!J2:J28) -> 2.8031683 | ... L7: =STDEV('Base de datos'!M2:M28) -> 5.1404783
A8: Probabilidad- | E8: =_xlfn.NORM.DIST(E$2/1.02,E6,E7,TRUE) -> 0 | G8: =_xlfn.NORM.DIST(G$2/1.02,G6,G7,TRUE) -> 0 | K8: =_xlfn.NORM.DIST(K$2/1.02,K6,K7,TRUE) -> 0
A9: Probabilidad+ | E9: =_xlfn.NORM.DIST(E$2*1.02,E6,E7,TRUE) -> 0 | G9: =_xlfn.NORM.DIST(G$2*1.02,G6,G7,TRUE) -> 0 | K9: =_xlfn.NORM.DIST(K$2*1.02,K6,K7,TRUE) -> 0
A10: Prob def | E10: =IF(E$2=0,1,E9-E8) -> 1 | G10: =IF(G$2=0,1,G9-G8) -> 1 | K10: =IF(K$2=0,1,K9-K8) -> 1 | N10: =$E10*$G10*$K10 -> 1 | O10: =N10*N11 -> 1 | P10: =O10/($O$213) -> 0.038461538 | Q10: =IF(P10=0,,"Abejero: "&P10) -> Abejero: 0,0384615384615385
A11: Si no | B11: =IF(OR(AND(B$2>MIN('Base de datos'!C2:C28)/1.05,B$2<MAX('Base de datos'!C2:C28)*1.05),B$2=0),1,0) -> 1 | C11: =IF(OR(AND(C$2>MIN('Base de datos'!D2:D28)/1.05,C$2<MAX('Base de datos'!D2:D28)*1.05),C$2=0),1,0) -> 1 | D11: =IF(OR(AND(D$2>MIN('Base de datos'!E2:E28)/1.05,D$2<MAX('Base de datos'!E2:E28)*1.05),D$2=0),1,0) -> 1 | E11: =IF(OR(AND(E$2>MIN('Base de datos'!F2:F28)/1.05,E$2<MAX('Base de datos'!F2:F28)*1.05),E$2=0),1,0) -> 1 | F11: =IF(OR(AND(F$2>MIN('Base de datos'!G2:G28)/1.05,F$2<MAX('Base de datos'!G2:G28)*1.05),F$2=0),1,0) -> 1 | G11: =IF(OR(AND(G$2>MIN('Base de datos'!H2:H28)/1.05,G$2<MAX('Base de datos'!H2:H28)*1.05),G$2=0),1,0) -> 1 | H11: =IF(OR(AND(H$2>MIN('Base de datos'!I2:I28)/1.05,H$2<MAX('Base de datos'!I2:I28)*1.05),H$2=0),1,0) -> 1 | I11: =IF(OR(AND(I$2>MIN('Base de datos'!J2:J28)/1.05,I$2<MAX('Base de datos'!J2:J28)*1.05),I$2=0),1,0) -> 1 | ... L11: =IF(OR(AND(L$2>MIN('Base de datos'!M2:M28)/1.05,L$2<MAX('Base de datos'!M2:M28)*1.05),L$2=0),1,0) -> 1 | N11: =PRODUCT(B11:L11) -> 1 | Q11: =IF(P11=0,,"Abejero: "&P11)
B12: coxalL | C12: coxalA | D12: esternon | E12: femur | F12: tibiotarso | G12: tarsometatarso | H12: Craneo a | I12: Craneo l | J12: humero | K12: cubito | L12: radio | Q12: =IF(P12=0,,"Abejero: "&P12)
A13: Alcotán | Q13: =IF(P13=0,,"Abejero: "&P13)
A14: Media | B14: =AVERAGE('Base de datos'!C29:C54) -> 31.169213 | C14: =AVERAGE('Base de datos'!D29:D54) -> 25.498399 | D14: =AVERAGE('Base de datos'!E29:E54) -> 44.085321 | E14: =AVERAGE('Base de datos'!F29:F54) -> 44.03977 | F14: =AVERAGE('Base de datos'!G29:G54) -> 57.356238 | G14: =AVERAGE('Base de datos'!H29:H54) -> 34.893363 | H14: =AVERAGE('Base de datos'!I29:I54) -> 29.141652 | I14: =AVERAGE('Base de datos'!J29:J54) -> 48.108896 | ... L14: =AVERAGE('Base de datos'!M29:M54) -> 59.200134 | Q14: =IF(P14=0,,"Abejero: "&P14)
A15: Desv Típica | B15: =STDEV('Base de datos'!C29:C54) -> 1.945086 | C15: =STDEV('Base de datos'!D29:D54) -> 1.4283426 | D15: =STDEV('Base de datos'!E29:E54) -> 2.3004908 | E15: =STDEV('Base de datos'!F29:F54) -> 1.4170065 | F15: =STDEV('Base de datos'!G29:G54) -> 1.7348037 | G15: =STDEV('Base de datos'!H29:H54) -> 0.92957315 | H15: =STDEV('Base de datos'!I29:I54) -> 0.87722331 | I15: =STDEV('Base de datos'!J29:J54) -> 1.8469387 | ... L15: =STDEV('Base de datos'!M29:M54) -> 3.6060854 | Q15: =IF(P15=0,,"Abejero: "&P15)
A16: Probabilidad- | E16: =_xlfn.NORM.DIST(E$2/1.02,E14,E15,TRUE) -> 0 | G16: =_xlfn.NORM.DIST(G$2/1.02,G14,G15,TRUE) -> 0 | K16: =_xlfn.NORM.DIST(K$2/1.02,K14,K15,TRUE) -> 0 | Q16: =IF(P16=0,,"Abejero: "&P16)
A17: Probabilidad+ | E17: =_xlfn.NORM.DIST(E$2*1.02,E14,E15,TRUE) -> 0 | G17: =_xlfn.NORM.DIST(G$2*1.02,G14,G15,TRUE) -> 0 | K17: =_xlfn.NORM.DIST(K$2*1.02,K14,K15,TRUE) -> 0 | Q17: =IF(P17=0,,"Abejero: "&(TEXT(P17,"0.0%")))
A18: Prob def | E18: =IF(E$2=0,1,E17-E16) -> 1 | G18: =IF(G$2=0,1,G17-G16) -> 1 | K18: =IF(K$2=0,1,K17-K16) -> 1 | N18: =$E18*$G18*$K18 -> 1 | O18: =N18*N19 -> 1 | P18: =O18/($O$213) -> 0.038461538 | Q18: =IF(P18=0,,"Abejero: "&(TEXT(P18,"0.0%"))) -> Abejero: 3,8%
A19: Si no | B19: =IF(OR(AND(B$2>MIN('Base de datos'!C29:C54)/1.05,B$2<MAX('Base de datos'!C29:C54)*1.05),B$2=0),1,0) -> 1 | C19: =IF(OR(AND(C$2>MIN('Base de datos'!D29:D54)/1.05,C$2<MAX('Base de datos'!D29:D54)*1.05),C$2=0),1,0) -> 1 | D19: =IF(OR(AND(D$2>MIN('Base de datos'!E29:E54)/1.05,D$2<MAX('Base de datos'!E29:E54)*1.05),D$2=0),1,0) -> 1 | E19: =IF(OR(AND(E$2>MIN('Base de datos'!F29:F54)/1.05,E$2<MAX('Base de datos'!F29:F54)*1.05),E$2=0),1,0) -> 1 | F19: =IF(OR(AND(F$2>MIN('Base de datos'!G29:G54)/1.05,F$2<MAX('Base de datos'!G29:G54)*1.05),F$2=0),1,0) -> 1 | G19: =IF(OR(AND(G$2>MIN('Base de datos'!H29:H54)/1.05,G$2<MAX('Base de datos'!H29:H54)*1.05),G$2=0),1,0) -> 1 | H19: =IF(OR(AND(H$2>MIN('Base de datos'!I29:I54)/1.05,H$2<MAX('Base de datos'!I29:I54)*1.05),H$2=0),1,0) -> 1 | I19: =IF(OR(AND(I$2>MIN('Base de datos'!J29:J54)/1.05,I$2<MAX('Base de datos'!J29:J54)*1.05),I$2=0),1,0) -> 1 | ... L19: =IF(OR(AND(L$2>MIN('Base de datos'!M29:M54)/1.05,L$2<MAX('Base de datos'!M29:M54)*1.05),L$2=0),1,0) -> 1 | N19: =PRODUCT(B19:L19) -> 1
B20: coxalL | C20: coxalA | D20: esternon | E20: femur | F20: tibiotarso | G20: tarsometatarso | H20: Craneo a | I20: Craneo l | J20: humero | K20: cubito | L20: radio
A21: Alimoche
A22: Media | B22: =AVERAGE('Base de datos'!C55:C90) -> 82.488283 | C22: =AVERAGE('Base de datos'!D55:D90) -> 44.973481 | D22: =AVERAGE('Base de datos'!E55:E90) -> 95.943287 | E22: =AVERAGE('Base de datos'!F55:F90) -> 75.124589 | F22: =AVERAGE('Base de datos'!G55:G90) -> 122.73177 | G22: =AVERAGE('Base de datos'!H55:H90) -> 80.232414 | H22: =AVERAGE('Base de datos'!I55:I90) -> 46.924725 | I22: =AVERAGE('Base de datos'!J55:J90) -> 106.03606 | ... L22: =AVERAGE('Base de datos'!M55:M90) -> 168.12178
A23: Desv Típica | B23: =STDEV('Base de datos'!C55:C90) -> 3.3558114 | C23: =STDEV('Base de datos'!D55:D90) -> 2.2736531 | D23: =STDEV('Base de datos'!E55:E90) -> 4.6702777 | E23: =STDEV('Base de datos'!F55:F90) -> 3.5673832 | F23: =STDEV('Base de datos'!G55:G90) -> 4.3312551 | G23: =STDEV('Base de datos'!H55:H90) -> 2.0624216 | H23: =STDEV('Base de datos'!I55:I90) -> 1.2083906 | I23: =STDEV('Base de datos'!J55:J90) -> 4.7631155 | ... L23: =STDEV('Base de datos'!M55:M90) -> 5.1158382
A24: Probabilidad- | E24: =_xlfn.NORM.DIST(E$2/1.02,E22,E23,TRUE) -> 0 | G24: =_xlfn.NORM.DIST(G$2/1.02,G22,G23,TRUE) -> 0 | K24: =_xlfn.NORM.DIST(K$2/1.02,K22,K23,TRUE) -> 0
A25: Probabilidad+ | E25: =_xlfn.NORM.DIST(E$2*1.02,E22,E23,TRUE) -> 0 | G25: =_xlfn.NORM.DIST(G$2*1.02,G22,G23,TRUE) -> 0 | K25: =_xlfn.NORM.DIST(K$2*1.02,K22,K23,TRUE) -> 0
A26: Prob def | E26: =IF(E$2=0,1,E25-E24) -> 1 | G26: =IF(G$2=0,1,G25-G24) -> 1 | K26: =IF(K$2=0,1,K25-K24) -> 1 | N26: =$E26*$G26*$K26 -> 1 | O26: =N26*N27 -> 1 | P26: =O26/($O$213) -> 0.038461538
A27: Si no | B27: =IF(OR(AND(B$2>MIN('Base de datos'!C55:C90)/1.05,B$2<MAX('Base de datos'!C55:C90)*1.05),B$2=0),1,0) -> 1 | C27: =IF(OR(AND(C$2>MIN('Base de datos'!D55:D90)/1.05,C$2<MAX('Base de datos'!D55:D90)*1.05),C$2=0),1,0) -> 1 | D27: =IF(OR(AND(D$2>MIN('Base de datos'!E55:E90)/1.05,D$2<MAX('Base de datos'!E55:E90)*1.05),D$2=0),1,0) -> 1 | E27: =IF(OR(AND(E$2>MIN('Base de datos'!F55:F90)/1.05,E$2<MAX('Base de datos'!F55:F90)*1.05),E$2=0),1,0) -> 1 | F27: =IF(OR(AND(F$2>MIN('Base de datos'!G55:G90)/1.05,F$2<MAX('Base de datos'!G55:G90)*1.05),F$2=0),1,0) -> 1 | G27: =IF(OR(AND(G$2>MIN('Base de datos'!H55:H90)/1.05,G$2<MAX('Base de datos'!H55:H90)*1.05),G$2=0),1,0) -> 1 | H27: =IF(OR(AND(H$2>MIN('Base de datos'!I55:I90)/1.05,H$2<MAX('Base de datos'!I55:I90)*1.05),H$2=0),1,0) -> 1 | I27: =IF(OR(AND(I$2>MIN('Base de datos'!J55:J90)/1.05,I$2<MAX('Base de datos'!J55:J90)*1.05),I$2=0),1,0) -> 1 | ... L27: =IF(OR(AND(L$2>MIN('Base de datos'!M55:M90)/1.05,L$2<MAX('Base de datos'!M55:M90)*1.05),L$2=0),1,0) -> 1 | N27: =PRODUCT(B27:L27) -> 1
B28: coxalL | C28: coxalA | D28: esternon | E28: femur | F28: tibiotarso | G28: tarsometatarso | H28: Craneo a | I28: Craneo l | J28: humero | K28: cubito | L28: radio
A29: Azor
A30: Media | B30: =AVERAGE('Base de datos'!C91:C124) -> 53.341176 | C30: =AVERAGE('Base de datos'!D91:D124) -> 37.873529 | D30: =AVERAGE('Base de datos'!E91:E124) -> 75.442759 | E30: =AVERAGE('Base de datos'!F91:F124) -> 77.935294 | F30: =AVERAGE('Base de datos'!G91:G124) -> 105.28855 | G30: =AVERAGE('Base de datos'!H91:H124) -> 77.312448 | H30: =AVERAGE('Base de datos'!I91:I124) -> 41.980553 | I30: =AVERAGE('Base de datos'!J91:J124) -> 71.96925 | ... L30: =AVERAGE('Base de datos'!M91:M124) -> 96.141128
A31: Desv Típica | B31: =STDEV('Base de datos'!C91:C124) -> 4.3817886 | C31: =STDEV('Base de datos'!D91:D124) -> 2.4388657 | D31: =STDEV('Base de datos'!E91:E124) -> 5.0452145 | E31: =STDEV('Base de datos'!F91:F124) -> 5.5723279 | F31: =STDEV('Base de datos'!G91:G124) -> 7.7363593 | G31: =STDEV('Base de datos'!H91:H124) -> 4.8531076 | H31: =STDEV('Base de datos'!I91:I124) -> 1.2280559 | I31: =STDEV('Base de datos'!J91:J124) -> 4.3881202 | ... L31: =STDEV('Base de datos'!M91:M124) -> 6.5062623
A32: Probabilidad- | E32: =_xlfn.NORM.DIST(E$2/1.02,E30,E31,TRUE) -> 0 | G32: =_xlfn.NORM.DIST(G$2/1.02,G30,G31,TRUE) -> 0 | K32: =_xlfn.NORM.DIST(K$2/1.02,K30,K31,TRUE) -> 0
A33: Probabilidad+ | E33: =_xlfn.NORM.DIST(E$2*1.02,E30,E31,TRUE) -> 0 | G33: =_xlfn.NORM.DIST(G$2*1.02,G30,G31,TRUE) -> 0 | K33: =_xlfn.NORM.DIST(K$2*1.02,K30,K31,TRUE) -> 0
A34: Prob def | E34: =IF(E$2=0,1,E33-E32) -> 1 | G34: =IF(G$2=0,1,G33-G32) -> 1 | K34: =IF(K$2=0,1,K33-K32) -> 1 | N34: =$E34*$G34*$K34 -> 1 | O34: =N34*N35 -> 1 | P34: =O34/($O$213) -> 0.038461538
A35: Si no | B35: =IF(OR(AND(B$2>MIN('Base de datos'!C91:C124)/1.05,B$2<MAX('Base de datos'!C91:C124)*1.05),B$2=0),1,0) -> 1 | C35: =IF(OR(AND(C$2>MIN('Base de datos'!D91:D124)/1.05,C$2<MAX('Base de datos'!D91:D124)*1.05),C$2=0),1,0) -> 1 | D35: =IF(OR(AND(D$2>MIN('Base de datos'!E91:E124)/1.05,D$2<MAX('Base de datos'!E91:E124)*1.05),D$2=0),1,0) -> 1 | E35: =IF(OR(AND(E$2>MIN('Base de datos'!F91:F124)/1.05,E$2<MAX('Base de datos'!F91:F124)*1.05),E$2=0),1,0) -> 1 | F35: =IF(OR(AND(F$2>MIN('Base de datos'!G91:G124)/1.05,F$2<MAX('Base de datos'!G91:G124)*1.05),F$2=0),1,0) -> 1 | G35: =IF(OR(AND(G$2>MIN('Base de datos'!H91:H124)/1.05,G$2<MAX('Base de datos'!H91:H124)*1.05),G$2=0),1,0) -> 1 | H35: =IF(OR(AND(H$2>MIN('Base de datos'!I91:I124)/1.05,H$2<MAX('Base de datos'!I91:I124)*1.05),H$2=0),1,0) -> 1 | I35: =IF(OR(AND(I$2>MIN('Base de datos'!J91:J124)/1.05,I$2<MAX('Base de datos'!J91:J124)*1.05),I$2=0),1,0) -> 1 | ... L35: =IF(OR(AND(L$2>MIN('Base de datos'!M91:M124)/1.05,L$2<MAX('Base de datos'!M91:M124)*1.05),L$2=0),1,0) -> 1 | N35: =PRODUCT(B35:L35) -> 1
B36: coxalL | C36: coxalA | D36: esternon | E36: femur | F36: tibiotarso | G36: tarsometatarso | H36: Craneo a | I36: Craneo l | J36: humero | K36: cubito | L36: radio
A37: B.Leonado
A38: Media | B38: =AVERAGE('Base de datos'!C125:C176) -> 140.5866 | C38: =AVERAGE('Base de datos'!D125:D176) -> 75.19559 | D38: =AVERAGE('Base de datos'!E125:E176) -> 168.89182 | E38: =AVERAGE('Base de datos'!F125:F176) -> 136.51565 | F38: =AVERAGE('Base de datos'!G125:G176) -> 196.0032 | G38: =AVERAGE('Base de datos'!H125:H176) -> 111.04852 | H38: =AVERAGE('Base de datos'!I125:I176) -> 56.279018 | I38: =AVERAGE('Base de datos'!J125:J176) -> 141.00643 | ... L38: =AVERAGE('Base de datos'!M125:M176) -> 316.86089
A39: Desv Típica | B39: =STDEV('Base de datos'!C125:C176) -> 6.176852 | C39: =STDEV('Base de datos'!D125:D176) -> 2.7044933 | D39: =STDEV('Base de datos'!E125:E176) -> 6.4683224 | E39: =STDEV('Base de datos'!F125:F176) -> 2.8708371 | F39: =STDEV('Base de datos'!G125:G176) -> 4.2466598 | G39: =STDEV('Base de datos'!H125:H176) -> 3.078969 | H39: =STDEV('Base de datos'!I125:I176) -> 1.9170842 | I39: =STDEV('Base de datos'!J125:J176) -> 3.4891892 | ... L39: =STDEV('Base de datos'!M125:M176) -> 8.2110664
A40: Probabilidad- | E40: =_xlfn.NORM.DIST(E$2/1.02,E38,E39,TRUE) -> 0 | G40: =_xlfn.NORM.DIST(G$2/1.02,G38,G39,TRUE) -> 0 | K40: =_xlfn.NORM.DIST(K$2/1.02,K38,K39,TRUE) -> 0
A41: Probabilidad+ | E41: =_xlfn.NORM.DIST(E$2*1.02,E38,E39,TRUE) -> 0 | G41: =_xlfn.NORM.DIST(G$2*1.02,G38,G39,TRUE) -> 0 | K41: =_xlfn.NORM.DIST(K$2*1.02,K38,K39,TRUE) -> 0
...

Sheet Base de datos
A1: IDENT | B1: Especie | C1: coxalL | D1: coxalA | E1: esternon | F1: femur | G1: tibiotarso | H1: tarsometatarso | I1: craneoancho | J1: craneolongitud | K1: humero | L1: cubito | M1: radio
A2: 484 | B2: Halcón Abejero | C2: 55.9 | D2: 32.1 | E2: 63.5 | F2: 54.1 | G2: 83.9 | H2: 51.1 | I2: 37.9 | J2: 73.6 | K2: 106.3 | L2: 115.2 | M2: 110.4
A3: 485 | B3: Halcón Abejero | C3: 57.4 | D3: 36.4 | E3: 69 | F3: 60 | G3: 91.8 | H3: 55.2 | I3: 40.1 | J3: 76.5 | K3: 110.3 | L3: 124.3 | M3: 117.1
A4: 486 | B4: Halcón Abejero | C4: 58.1 | D4: 33.2 | E4: 65.7 | F4: 57.5 | G4: 88.4 | H4: 53.9 | I4: 38.7 | J4: 74 | K4: 107.3 | L4: 118.4 | M4: 112.1
A5: 487 | B5: Halcón Abejero | C5: 60.1 | D5: 35.1 | E5: 65.6 | F5: 55.5 | G5: 86.5 | H5: 52.7 | I5: 39.7 | J5: 75 | K5: 103.4 | L5: 115.91918 | M5: 108.58282
A6: 488 | B6: Halcón Abejero | C6: 56.7 | D6: 32.2 | E6: 58.7 | F6: 55.1 | G6: 85.9 | H6: 53 | I6: 35.3 | J6: 70.604341 | K6: 104.3 | L6: 111.2 | M6: 108.9
A7: 489 | B7: Halcón Abejero | C7: 51.9 | D7: 33 | E7: 67.9 | F7: 57 | G7: 89.3 | H7: 55.209233 | I7: 39.8 | J7: 80 | K7: 107.3 | L7: 121.8 | M7: 117.8
A8: 490 | B8: Halcón Abejero | C8: 61.3 | D8: 31 | E8: 65.9 | F8: 57.4 | G8: 87.2 | H8: 51.4 | I8: 39.4 | J8: 77.848545 | K8: 108 | L8: 120.7 | M8: 115.9
A9: 491 | B9: Halcón Abejero | C9: 59.9 | D9: 34.5 | E9: 63.1 | F9: 54.6 | G9: 85.9 | H9: 54.2 | I9: 40.6 | J9: 75.5 | K9: 102.3 | L9: 115.2 | M9: 108.2
A10: 492 | B10: Halcón Abejero | C10: 59.3 | D10: 33 | E10: 61.3 | F10: 53.9 | G10: 83 | H10: 49.7 | I10: 38 | J10: 70.764937 | K10: 104.2 | L10: 113.8 | M10: 106
A11: 493 | B11: Halcón Abejero | C11: 61.2 | D11: 33.9 | E11: 68.1 | F11: 62.5 | G11: 92.3 | H11: 56.1 | I11: 38.9 | J11: 76.4 | K11: 115 | L11: 126.2 | M11: 119.1
A12: 494 | B12: Halcón Abejero | C12: 57.4 | D12: 33.7 | E12: 63.7 | F12: 57.3 | G12: 87.1 | H12: 53.8 | I12: 38.8 | J12: 74.2 | K12: 105.24431 | L12: 115 | M12: 108.6
A13: 495 | B13: Halcón Abejero | C13: 56.8 | D13: 31.8 | E13: 60 | F13: 56.5 | G13: 87.9 | H13: 49.7 | I13: 37.2 | J13: 71.7 | K13: 108.3 | L13: 120.9 | M13: 114.7
... A852: 342 | B852: Águila Real | C852: 86.8 | D852: 58.4 | E852: 111.1 | F852: 121.8 | G852: 167.8 | H852: 104 | I852: 60.7 | J852: 112 | K852: 177.6 | L852: 208.2 | M852: 197.7
